Workbook

Sheet data_imperial
A1: Baseline | B1: Cost of Production per acre | C1: mean ($/acre) | D1: std.err ($/acre) | E1: Producer price ($/lb.) | F1: Cleaner Aggregator | G1: Primary Processor | H1: Secondary Processor | I1: Wholesale / Distributor
A2: Consumer | B2: cost_of_production_drybean_more_mill_nonmwbe_conv
B3: cost_of_production_drybean_more_mill_mwbe_conv
B4: cost_of_production_drybean_less_mill_nonmwbe_conv
B5: cost_of_production_drybean_less_mill_mwbe_conv
B6: cost_of_production_drybean_more_mill_nonmwbe_org
B7: cost_of_production_drybean_more_mill_mwbe_org
B8: cost_of_production_drybean_less_mill_nonmwbe_org
B9: cost_of_production_drybean_less_mill_mwbe_org
B10: cost_of_production_outsideNY
A11: Differentiated | B11: cost_of_production_drybean_more_mill_nonmwbe_conv | C11: 493.75 | D11: 148.4375 | E11: 0.75 | F11: organic | G11: conventional & organic | H11: organic and conventional | I11: conventional & organic
B12: cost_of_production_drybean_more_mill_mwbe_conv | E12: 0.75 | F12: 0.11 | G12: canning | H12: frozen/processed (not canned) beans | I12: dry beans
B13: cost_of_production_drybean_less_mill_nonmwbe_conv | C13: 343.75 | D13: 125 | E13: 0.75 | G13: 6-10% | H13: 8-10% | I13: 20-24%
B14: cost_of_production_drybean_less_mill_mwbe_conv | C14: 375 | D14: 140.625 | E14: 0.75 | F14: conventional
B15: cost_of_production_drybean_more_mill_nonmwbe_org | E15: 1.05 | F15: 4-9% | G15: conventional & organic | I15: conventional & organic
B16: cost_of_production_drybean_more_mill_mwbe_org | E16: 1.05 | G16: dry beans bagging | I16: canned beans
B17: cost_of_production_drybean_less_mill_nonmwbe_org | C17: 625 | D17: 156.25 | E17: 1.05 | G17: 15-20% | I17: 22-26%
B18: cost_of_production_drybean_less_mill_mwbe_org | E18: 1.05
B19: cost_of_production_outsideNY | C19: 471.83 | D19: 43.761457 | F19: N/A
A20: NYC Public Institutions | B20: cost_of_production_drybean_more_mill_nonmwbe_conv | C20: 493.75 | D20: 148.4375 | F20: organic | G20: conventional & organic | H20: organic and conventional | I20: conventional & organic
B21: cost_of_production_drybean_more_mill_mwbe_conv | F21: 0.11 | G21: canning | H21: frozen/processed (not canned) beans | I21: dry beans
B22: cost_of_production_drybean_less_mill_nonmwbe_conv | C22: 343.75 | D22: 125 | G22: 6-10% | H22: 8-10% | I22: medium sized: 8-10%
B23: cost_of_production_drybean_less_mill_mwbe_conv | C23: 375 | D23: 140.625 | F23: conventional | I23: large: 3-5%
B24: cost_of_production_drybean_more_mill_nonmwbe_org | F24: 4-9% | G24: conventional & organic
B25: cost_of_production_drybean_more_mill_mwbe_org | G25: dry beans bagging | I25: conventional & organic
B26: cost_of_production_drybean_less_mill_nonmwbe_org | C26: 625 | D26: 156.25 | G26: 15-20% | I26: canned beans
B27: cost_of_production_drybean_less_mill_mwbe_org | I27: medium sized: 8-10%
B28: cost_of_production_outsideNY | C28: 471.83 | D28: 43.761457 | G28: 6-10% (Conventional & Organic: Furmanos) | I28: large: 3-5%
A29: Commodity | B29: cost_of_production_drybean_more_mill_nonmwbe_conv | C29: 493.75 | D29: 148.4375 | E29: 0.405 | F29: organic | G29: conventional & organic | H29: organic and conventional | I29: conventional & organic
B30: cost_of_production_drybean_more_mill_mwbe_conv | E30: 0.405 | F30: 0.11 | G30: canning | H30: frozen/processed (not canned) beans | I30: dry beans
B31: cost_of_production_drybean_less_mill_nonmwbe_conv | C31: 343.75 | D31: 125 | E31: 0.405 | G31: xxx | H31: 8-10% | I31: medium sized: 8-10%
B32: cost_of_production_drybean_less_mill_mwbe_conv | C32: 375 | D32: 140.625 | E32: 0.405 | F32: conventional | I32: large: 3-5%
B33: cost_of_production_drybean_more_mill_nonmwbe_org | E33: 0.405 | F33: 4-9% | G33: conventional & organic
B34: cost_of_production_drybean_more_mill_mwbe_org | E34: 0.405 | G34: dry beans bagging | I34: conventional & organic
B35: cost_of_production_drybean_less_mill_nonmwbe_org | C35: 625 | D35: 156.25 | E35: 0.405 | G35: 15-20% | I35: canned beans
B36: cost_of_production_drybean_less_mill_mwbe_org | E36: 0.405 | I36: medium sized: 8-10%
B37: cost_of_production_outsideNY | C37: 471.83 | D37: 43.761457 | E37: 0.405 | G37: 6-10% (Conventional & Organic canning: Furmanos); 15-20% dry beans bagging | I37: large: 3-5%
A38: Soybeans | B38: cost_of_production_soy_more_mill_nonmwbe_conv | C38: 815.09434 | D38: 37.735849 | E38: 0.2366667
B39: cost_of_production_soy_more_mill_mwbe_conv | C39: 815.09434 | D39: 75.471698 | E39: 0.2366667
B40: cost_of_production_soy_less_mill_nonmwbe_conv | C40: 822.64151 | D40: 15.09434 | E40: 0.2366667
...

Sheet producer_data_metric
A1: Baseline | B1: Cost of Production per acre | C1: mean ($/hectare) | D1: std.err ($/hectare) | E1: Producer price ($/kg.)
A2: Consumer | B2: cost_of_production_drybean_more_mill_nonmwbe_conv
B3: cost_of_production_drybean_more_mill_mwbe_conv
B4: cost_of_production_drybean_less_mill_nonmwbe_conv
B5: cost_of_production_drybean_less_mill_mwbe_conv
B6: cost_of_production_drybean_more_mill_nonmwbe_org
B7: cost_of_production_drybean_more_mill_mwbe_org
B8: cost_of_production_drybean_less_mill_nonmwbe_org
B9: cost_of_production_drybean_less_mill_mwbe_org
B10: cost_of_production_outsideNY
A11: Differentiated | B11: cost_of_production_drybean_more_mill_nonmwbe_conv | C11: =data_imperial!C11*2.471 -> 1220.0563 | D11: =data_imperial!D11*2.471 -> 366.78906 | E11: =data_imperial!E11*2.20462 -> 1.653465
B12: cost_of_production_drybean_more_mill_mwbe_conv | E12: =data_imperial!E12*2.20462 -> 1.653465
B13: cost_of_production_drybean_less_mill_nonmwbe_conv | C13: =data_imperial!C13*2.471 -> 849.40625 | D13: =data_imperial!D13*2.471 -> 308.875 | E13: =data_imperial!E13*2.20462 -> 1.653465
B14: cost_of_production_drybean_less_mill_mwbe_conv | C14: =data_imperial!C14*2.471 -> 926.625 | D14: =data_imperial!D14*2.471 -> 347.48438 | E14: =data_imperial!E14*2.20462 -> 1.653465
B15: cost_of_production_drybean_more_mill_nonmwbe_org | E15: =data_imperial!E15*2.20462 -> 2.314851
B16: cost_of_production_drybean_more_mill_mwbe_org | E16: =data_imperial!E16*2.20462 -> 2.314851
B17: cost_of_production_drybean_less_mill_nonmwbe_org | C17: =data_imperial!C17*2.471 -> 1544.375 | D17: =data_imperial!D17*2.471 -> 386.09375 | E17: =data_imperial!E17*2.20462 -> 2.314851
B18: cost_of_production_drybean_less_mill_mwbe_org | E18: =data_imperial!E18*2.20462 -> 2.314851
B19: cost_of_production_outsideNY | C19: =data_imperial!C19*2.471 -> 1165.8919 | D19: =data_imperial!D19*2.471 -> 108.13456 | E19: =data_imperial!E19*2.20462 -> 0
A20: NYC Public Institutions | B20: cost_of_production_drybean_more_mill_nonmwbe_conv | C20: =data_imperial!C20*2.471 -> 1220.0563 | D20: =data_imperial!D20*2.471 -> 366.78906 | E20: =data_imperial!E20*2.20462 -> 0
B21: cost_of_production_drybean_more_mill_mwbe_conv | E21: =data_imperial!E21*2.20462 -> 0
B22: cost_of_production_drybean_less_mill_nonmwbe_conv | C22: =data_imperial!C22*2.471 -> 849.40625 | D22: =data_imperial!D22*2.471 -> 308.875 | E22: =data_imperial!E22*2.20462 -> 0
B23: cost_of_production_drybean_less_mill_mwbe_conv | C23: =data_imperial!C23*2.471 -> 926.625 | D23: =data_imperial!D23*2.471 -> 347.48438 | E23: =data_imperial!E23*2.20462 -> 0
B24: cost_of_production_drybean_more_mill_nonmwbe_org | E24: =data_imperial!E24*2.20462 -> 0
B25: cost_of_production_drybean_more_mill_mwbe_org | E25: =data_imperial!E25*2.20462 -> 0
B26: cost_of_production_drybean_less_mill_nonmwbe_org | C26: =data_imperial!C26*2.471 -> 1544.375 | D26: =data_imperial!D26*2.471 -> 386.09375 | E26: =data_imperial!E26*2.20462 -> 0
B27: cost_of_production_drybean_less_mill_mwbe_org | E27: =data_imperial!E27*2.20462 -> 0
B28: cost_of_production_outsideNY | C28: =data_imperial!C28*2.471 -> 1165.8919 | D28: =data_imperial!D28*2.471 -> 108.13456 | E28: =data_imperial!E28*2.20462 -> 0
A29: Commodity | B29: cost_of_production_drybean_more_mill_nonmwbe_conv | C29: =data_imperial!C29*2.471 -> 1220.0563 | D29: =data_imperial!D29*2.471 -> 366.78906 | E29: =data_imperial!E29*2.20462 -> 0.8928711
B30: cost_of_production_drybean_more_mill_mwbe_conv | E30: =data_imperial!E30*2.20462 -> 0.8928711
B31: cost_of_production_drybean_less_mill_nonmwbe_conv | C31: =data_imperial!C31*2.471 -> 849.40625 | D31: =data_imperial!D31*2.471 -> 308.875 | E31: =data_imperial!E31*2.20462 -> 0.8928711
B32: cost_of_production_drybean_less_mill_mwbe_conv | C32: =data_imperial!C32*2.471 -> 926.625 | D32: =data_imperial!D32*2.471 -> 347.48438 | E32: =data_imperial!E32*2.20462 -> 0.8928711
B33: cost_of_production_drybean_more_mill_nonmwbe_org | E33: =data_imperial!E33*2.20462 -> 0.8928711
B34: cost_of_production_drybean_more_mill_mwbe_org | E34: =data_imperial!E34*2.20462 -> 0.8928711
B35: cost_of_production_drybean_less_mill_nonmwbe_org | C35: =data_imperial!C35*2.471 -> 1544.375 | D35: =data_imperial!D35*2.471 -> 386.09375 | E35: =data_imperial!E35*2.20462 -> 0.8928711
B36: cost_of_production_drybean_less_mill_mwbe_org | E36: =data_imperial!E36*2.20462 -> 0.8928711
B37: cost_of_production_outsideNY | C37: =data_imperial!C37*2.471 -> 1165.8919 | D37: =data_imperial!D37*2.471 -> 108.13456 | E37: =data_imperial!E37*2.20462 -> 0.8928711
A38: Soybeans | B38: cost_of_production_soy_more_mill_nonmwbe_conv | E38: =data_imperial!E38*2.20462 -> 0.52176014
B39: cost_of_production_soy_more_mill_mwbe_conv | E39: =data_imperial!E39*2.20462 -> 0.52176014
B40: cost_of_production_soy_less_mill_nonmwbe_conv | C40: =data_imperial!C40*2.471 -> 2032.7472 | D40: =data_imperial!D40*2.471 -> 37.298113 | E40: =data_imperial!E40*2.20462 -> 0.52176014
...

Sheet info
A1: We are not modeling the direct to consumer market, the top row
A3: Sources:
A4: Cost of production for dry beans: out of state is based on enterprise budgets from North Dakota, Colorado, Wyoming and Texas. In-state is based on a cost of production per acre of xx, which is then increased/decreased for each type of farm based on Census of Agriculture data (see farmgate_pricing.qmd)
A5: Cost of production for soybeans: not included for out of state. In-state is based on Census of Agriculture data for producers that have soy only. We only have data for <$1 conventional.
A7: Price data is from 2022 and based on cost data in the same year

Sheet price worksheet
A1: Goya wholesale price | B1: price per lb.
A2: $0.07/Ounce | B2: =0.07*16 -> 1.12
A4: NY Bean sells to Goya
A5: $57 for a 50lb bafg
A6: =57/50 -> 1.14
A10: 38.82
A11: 24
A12: 15.15
A13: =A10/A11 -> 1.6175
A14: =A13/A12 -> 0.10676568
A15: =A14*16 -> 1.7082508 | B15: price per lb for organic canned beans
A18: Cleaner/aggregator outside of margin
A19: Grower is getting | B19: 0.405
A20: NYC is paying an average of | B20: 0.74 | C20: canned beans

Sheet CO_Example
A1: Scenario | B1: Price Received by Farmer (Note: All prices in table are in $/lb.) | C1: Price Received by Shipper/Warehouse | D1: Price Received by Processor | E1: Price Received by Distributor
A2: Baseline | B2: 0.09051 | C2: 0.3582 | D2: 0.518 | E2: 1.013
B3: (NPC Yearbook ID avg. price) | C3: (CO-originated terminal market avg. price 1998-2019 for Russet conventional) | D3: (ERS food dollar: processor) | E3: (DPS data)
A4: Local | B4: Russet conventional: $0.1291 | C4: Russet conventional: $0.358 | D4: N/A | E4: Russet conv: $0.36056,10
B5: Russet organic: $0.2546 | C5: Russet organic: $0.705 | E5: ($0.35 DPS data + 3% change baseline to local through mainline dist.10)
B6: Specialty conv.: $0.2350 | C6: Specialty conv.: $0.651 | E6: Russet organic: $0.710
B7: Specialty organic: $0.46344 | C7: Specialty organic: $1.284 | E7: Specialty conv.: $ 0.656
B8: Repacker: $0.08105 | C8: Repacker: $0.224 | E8: Specialty organic: $ 1.293
B9: (AMS 1998-2019; CPAC report) | C9: (177% premium over FG from Russet conv.)
A10: Short supply chain | B10: Russet conventional: $.222 | C10: Russet conventional: $0.358 | D10: N/A | E10: N/A
B11: Russet organic: $0.437 | C11: Russet organic: $0.705
B12: Specialty conv.: $0.404 | C12: Specialty conv.: $0.651
B13: Specialty organic: $0.796 | C13: Specialty organic: $1.284
B14: Repacker: $0.139 | C14: Repacker: $0.224
B15: (62% to farmer and 38% to shipper cost structure from AAEA pres.9) | C15: (From scenario 2)
A16: Seconds (waste reduction) | B16: 0.03567 | C16: 0.0986 | D16: N/A | E16: N/A
C17: ($0.0356 farmgate + 177% from scenario 2)
A18: Value-added | B18: Russet conventional: $.1291 | C18: Russet conventional: $0.358 | D18: Russet conv: $0.518 | E18: 0.828
B19: Russet organic: $.2546 | C19: Russet organic: $0.705 | D19: (From scenario 1) | E19: (price for frozen, seasoned, diced potatoes from DPS data)
B20: Specialty conventional: $.2350 | C20: Specialty conv.: $0.651 | D20: Russet organic: $1.004 | E20: Russet organic: $1.614
B21: Specialty organic: $.4634 | C21: Specialty organic: $1.284 | D21: Specialty conv: $0.927 | E21: Specialty conv: $1.490
B22: (From scenario 2) | C22: Repacker price: $0.224 | D22: Specialty org: $1.829 | E22: Specialty org: $2.941
C23: (From scenario 2)
